 Fri, 06 Mar 2020 12:58:32  INFO test_login.py setUpClass [ line:39 ] ==================== 准备开始执行登录接口测试 ====================
 Fri, 06 Mar 2020 12:58:33  INFO http_request.py request [ line:56 ] 正在发送请求，请求地址：http://118.24.221.133:8081/futureloan/mvc/api/member/login， 请求参数：{"mobilephone":"13342884220", "pwd":"123456"}
 Fri, 06 Mar 2020 12:58:33  ERROR test_login.py test_login [ line:70 ] {'status': 1, 'code': '10001', 'data': None, 'msg': '登录成功'} != {'status': 0, 'code': '20103', 'data': None, 'msg': '手机号不能为空'}
- {'code': '10001', 'data': None, 'msg': '登录成功', 'status': 1}
?             ^^^                         ^^^^             ^

+ {'code': '20103', 'data': None, 'msg': '手机号不能为空', 'status': 0}
?           ++  ^                         ^^^^^^^             ^
Traceback (most recent call last):
  File "/Users/huangjie/学习/untitled7/test_cases/test_login.py", line 67, in test_login
    self.assertEqual(eval(case.expected_data), res)
  File "/Library/Frameworks/Python.framework/Versions/3.7/lib/python3.7/unittest/case.py", line 852, in assertEqual
    assertion_func(first, second, msg=msg)
  File "/Library/Frameworks/Python.framework/Versions/3.7/lib/python3.7/unittest/case.py", line 1151, in assertDictEqual
    self.fail(self._formatMessage(msg, standardMsg))
  File "/Library/Frameworks/Python.framework/Versions/3.7/lib/python3.7/unittest/case.py", line 693, in fail
    raise self.failureException(msg)
AssertionError: {'status': 1, 'code': '10001', 'data': None, 'msg': '登录成功'} != {'status': 0, 'code': '20103', 'data': None, 'msg': '手机号不能为空'}
- {'code': '10001', 'data': None, 'msg': '登录成功', 'status': 1}
?             ^^^                         ^^^^             ^

+ {'code': '20103', 'data': None, 'msg': '手机号不能为空', 'status': 0}
?           ++  ^                         ^^^^^^^             ^

 Fri, 06 Mar 2020 12:58:33  INFO http_request.py request [ line:56 ] 正在发送请求，请求地址：http://118.24.221.133:8081/futureloan/mvc/api/member/login， 请求参数：{"mobilephone":"150 71369970", "pwd":"123456"}
 Fri, 06 Mar 2020 12:58:33  ERROR test_login.py test_login [ line:70 ] {'status': 0, 'code': '20111', 'data': None, 'msg': '用户名或密码错误'} != {'status': 0, 'code': '20103', 'data': None, 'msg': '手机号不能为空'}
- {'code': '20111', 'data': None, 'msg': '用户名或密码错误', 'status': 0}
?              ^^                         ^^^^^^^^

+ {'code': '20103', 'data': None, 'msg': '手机号不能为空', 'status': 0}
?              ^^                         ^^^^^^^
Traceback (most recent call last):
  File "/Users/huangjie/学习/untitled7/test_cases/test_login.py", line 67, in test_login
    self.assertEqual(eval(case.expected_data), res)
  File "/Library/Frameworks/Python.framework/Versions/3.7/lib/python3.7/unittest/case.py", line 852, in assertEqual
    assertion_func(first, second, msg=msg)
  File "/Library/Frameworks/Python.framework/Versions/3.7/lib/python3.7/unittest/case.py", line 1151, in assertDictEqual
    self.fail(self._formatMessage(msg, standardMsg))
  File "/Library/Frameworks/Python.framework/Versions/3.7/lib/python3.7/unittest/case.py", line 693, in fail
    raise self.failureException(msg)
AssertionError: {'status': 0, 'code': '20111', 'data': None, 'msg': '用户名或密码错误'} != {'status': 0, 'code': '20103', 'data': None, 'msg': '手机号不能为空'}
- {'code': '20111', 'data': None, 'msg': '用户名或密码错误', 'status': 0}
?              ^^                         ^^^^^^^^

+ {'code': '20103', 'data': None, 'msg': '手机号不能为空', 'status': 0}
?              ^^                         ^^^^^^^

 Fri, 06 Mar 2020 12:58:33  INFO test_login.py tearDownClass [ line:45 ] ==================== 登录接口测试执行完毕====================
